Workbook

Sheet Executive Summary
A1: CENTRE FOR MEDICAL TECHNOLOGIES (IDRP) | IIT JODHPUR & AIIMS JODHPUR
A2: Official Student & Scholar Master Registry • Cohorts 2020 – 2026 • Verified Institute Data
A4: TOTAL SCHOLARS | C4: M.TECH (MASTERS) | E4: PH.D. SCHOLARS | G4: DUAL DEGREE (M.TECH-PH.D.) | I4: ACTIVE ENROLLED | J4: ALUMNI / GRADUATES
A5: =COUNTA('Master Directory'!$B$5:$B$111) | C5: =COUNTIF('Master Directory'!$D$5:$D$111, "Masters") | E5: =COUNTIF('Master Directory'!$D$5:$D$111, "PhD") | G5: =COUNTIF('Master Directory'!$D$5:$D$111, "Dual Degree") | I5: =COUNTIF('Master Directory'!$H$5:$H$111, "Active") | J5: =COUNTIF('Master Directory'!$H$5:$H$111, "Alumni")
A7: 1. COHORT ENROLLMENT MATRIX BY ADMISSION YEAR & DEGREE PROGRAM
A8: Admission Cohort Year | B8: M.Tech (Masters) | C8: Ph.D. Scholars | D8: Dual Degree (M.Tech-Ph.D.) | E8: Total Cohort Intake | F8: % of Total Intake | G8: Academic Status
A9: 2020 | B9: =COUNTIFS('Master Directory'!$F$5:$F$111, $A9, 'Master Directory'!$D$5:$D$111, "Masters") | C9: =COUNTIFS('Master Directory'!$F$5:$F$111, $A9, 'Master Directory'!$D$5:$D$111, "PhD") | D9: =COUNTIFS('Master Directory'!$F$5:$F$111, $A9, 'Master Directory'!$D$5:$D$111, "Dual Degree") | E9: =SUM(B9:D9) | F9: =E9/$E$16 | G9: Alumni (Graduated)
A10: 2021 | B10: =COUNTIFS('Master Directory'!$F$5:$F$111, $A10, 'Master Directory'!$D$5:$D$111, "Masters") | C10: =COUNTIFS('Master Directory'!$F$5:$F$111, $A10, 'Master Directory'!$D$5:$D$111, "PhD") | D10: =COUNTIFS('Master Directory'!$F$5:$F$111, $A10, 'Master Directory'!$D$5:$D$111, "Dual Degree") | E10: =SUM(B10:D10) | F10: =E10/$E$16 | G10: Alumni (Graduated)
A11: 2022 | B11: =COUNTIFS('Master Directory'!$F$5:$F$111, $A11, 'Master Directory'!$D$5:$D$111, "Masters") | C11: =COUNTIFS('Master Directory'!$F$5:$F$111, $A11, 'Master Directory'!$D$5:$D$111, "PhD") | D11: =COUNTIFS('Master Directory'!$F$5:$F$111, $A11, 'Master Directory'!$D$5:$D$111, "Dual Degree") | E11: =SUM(B11:D11) | F11: =E11/$E$16 | G11: Alumni (Graduated)
A12: 2023 | B12: =COUNTIFS('Master Directory'!$F$5:$F$111, $A12, 'Master Directory'!$D$5:$D$111, "Masters") | C12: =COUNTIFS('Master Directory'!$F$5:$F$111, $A12, 'Master Directory'!$D$5:$D$111, "PhD") | D12: =COUNTIFS('Master Directory'!$F$5:$F$111, $A12, 'Master Directory'!$D$5:$D$111, "Dual Degree") | E12: =SUM(B12:D12) | F12: =E12/$E$16 | G12: Alumni (Graduated)
A13: 2024 | B13: =COUNTIFS('Master Directory'!$F$5:$F$111, $A13, 'Master Directory'!$D$5:$D$111, "Masters") | C13: =COUNTIFS('Master Directory'!$F$5:$F$111, $A13, 'Master Directory'!$D$5:$D$111, "PhD") | D13: =COUNTIFS('Master Directory'!$F$5:$F$111, $A13, 'Master Directory'!$D$5:$D$111, "Dual Degree") | E13: =SUM(B13:D13) | F13: =E13/$E$16 | G13: Graduating / Active
A14: 2025 | B14: =COUNTIFS('Master Directory'!$F$5:$F$111, $A14, 'Master Directory'!$D$5:$D$111, "Masters") | C14: =COUNTIFS('Master Directory'!$F$5:$F$111, $A14, 'Master Directory'!$D$5:$D$111, "PhD") | D14: =COUNTIFS('Master Directory'!$F$5:$F$111, $A14, 'Master Directory'!$D$5:$D$111, "Dual Degree") | E14: =SUM(B14:D14) | F14: =E14/$E$16 | G14: Active Enrolled
A15: 2026 | B15: =COUNTIFS('Master Directory'!$F$5:$F$111, $A15, 'Master Directory'!$D$5:$D$111, "Masters") | C15: =COUNTIFS('Master Directory'!$F$5:$F$111, $A15, 'Master Directory'!$D$5:$D$111, "PhD") | D15: =COUNTIFS('Master Directory'!$F$5:$F$111, $A15, 'Master Directory'!$D$5:$D$111, "Dual Degree") | E15: =SUM(B15:D15) | F15: =E15/$E$16 | G15: Active Enrolled
A16: TOTAL ALL COHORTS | B16: =SUM(B9:B15) | C16: =SUM(C9:C15) | D16: =SUM(D9:D15) | E16: =SUM(E9:E15) | F16: =SUM(F9:F15) | G16: 100% Verified Records
A18: 2. STUDENT INNOVATION, TRANSLATIONAL IP & ENTREPRENEURSHIP IMPACT
A19: Innovation Pillar | B19: Student Scholar Metric | C19: Scholars Count | D19: Key Contributing Scholars & Translational Output Summary
A20: Intellectual Property (Patents) | B20: Scholars with Filed / Granted Patents | C20: =COUNTIF('Master Directory'!$O$5:$O$111, ">0") | D20: 16 Scholars | 28 Indian Patents (Dental irrigation, Robot echocardiography, Bilirubin, Bioinks, Paper-based glucose biosensors, Phototherapy)
A21: Incubated Healthcare Startups | B21: Student-Founded / Co-Founded Ventures | C21: =COUNTIF('Master Directory'!$Q$5:$Q$111, ">0") | D21: 11 Scholars | Healyantra, Caldor Health, Medvocare, Cellverse, NxGen Healtech, Sarbit Innovations, Visionence, ShilpinMed
A22: Peer-Reviewed Publications | B22: Scholars with Published Papers / Responses | C22: =COUNTIF('Master Directory'!$M$5:$M$111, ">0") | D22: 14 Scholars | Journals (Frontiers in Public Health, ACS, IEEE Nanomed), Conferences (MICCAI, IJCAI, FENS Denmark, EMBL)
A23: National & State Awards | B23: Scholars with Prestigious Honors | C23: =COUNTIF('Master Directory'!$S$5:$S$111, ">0") | D23: iStart Rajasthan 1st Prize, AIIMS-IIT Joint Innovation Honors, MedTech Pitch Winners

Sheet Master Directory
A1: CENTRE FOR MEDICAL TECHNOLOGIES (IDRP) | IIT JODHPUR & AIIMS JODHPUR
A2: Consolidated Master Directory of All 107 Medical Technology Scholars (2020 – 2026 Batches)
A4: S.No. | B4: Roll Number | C4: Student Scholar Name | D4: Program Level | E4: Degree Program | F4: Cohort Year | G4: Graduation Year | H4: Academic Status | I4: Specialization & Research Focus | J4: Faculty Supervisor(s) (IIT & AIIMS) | K4: Institutional Email | L4: Contact Phone | M4: Publications (Count) | N4: Publication Venues & Papers | O4: Patents (Count) | P4: Patent Filings & Application Nos. | Q4: Startups (Count) | R4: Startup Ventures & Student Roles | S4: Awards (Count) | T4: Awards, Honors & Hackathon Wins | U4: Date of Birth | V4: Gender | W4: Department / Centre | X4: Campus / Residential Address | Y4: City | Z4: State | AA4: Pincode | AB4: Verification Source URL / Provenance
A5: 1 | B5: M20ID001 | C5: Anup Kamal Kakwani | D5: Masters | E5: M.Tech in Medical Technology | F5: 2020 | G5: 2022 | H5: Alumni | I5: Endodontics & Dental Irrigation Systems | J5: Dr. Pravin Kumar (AIIMS Jodhpur) & Dr. Jaiveer Singh (IIT Jodhpur) | K5: m20id001@iitj.ac.in | L5: - | M5: 0 | N5: - | O5: 1 | P5: App #202211041593: A Cost Effective and User Friendly System to Irrigate Root Canal Under Apical Negative Pressure (Published) | App 202211041593: Root Canal Irrigation System Under Apical Negative Pressure | Q5: 1 | R5: NxGen Healtech Pvt. Ltd. (Founder & Managing Director, Pre-Incubatee) | NxGen Healtech Pvt. Ltd. (Founder) | S5: 0 | T5: - | U5: - | V5: - | W5: Centre for Medical Technologies (IDRP) | X5: IIT Jodhpur Permanent Campus, NH 62, Karwar | Y5: Jodhpur | Z5: Rajasthan | AA5: 342030 | AB5: Official Cohort Registry (IIT Jodhpur MedTech Portal)
A6: 2 | B6: M20ID002 | C6: Anushri Bhardwaj | D6: Masters | E6: M.Tech in Medical Technology | F6: 2020 | G6: 2022 | H6: Alumni | I6: Medical Technology | J6: Faculty Board (IDRP / AIIMS-IIT Joint) | K6: m20id002@iitj.ac.in | L6: - | M6: 0 | N6: - | O6: 0 | P6: - | Q6: 0 | R6: - | S6: 0 | T6: - | U6: - | V6: - | W6: Centre for Medical Technologies (IDRP) | X6: IIT Jodhpur Permanent Campus, NH 62, Karwar | Y6: Jodhpur | Z6: Rajasthan | AA6: 342030 | AB6: Official Cohort Registry (IIT Jodhpur MedTech Portal)
A7: 3 | B7: M20ID004 | C7: Mridul Sharma | D7: Masters | E7: M.Tech in Medical Technology | F7: 2020 | G7: 2022 | H7: Alumni | I7: Medical Technology | J7: Faculty Board (IDRP / AIIMS-IIT Joint) | K7: m20id004@iitj.ac.in | L7: - | M7: 0 | N7: - | O7: 0 | P7: - | Q7: 0 | R7: - | S7: 0 | T7: - | U7: - | V7: - | W7: Centre for Medical Technologies (IDRP) | X7: IIT Jodhpur Permanent Campus, NH 62, Karwar | Y7: Jodhpur | Z7: Rajasthan | AA7: 342030 | AB7: Official Cohort Registry (IIT Jodhpur MedTech Portal)
A8: 4 | B8: M20ID005 | C8: Shradha Suman Panda | D8: Masters | E8: M.Tech in Medical Technology | F8: 2020 | G8: 2022 | H8: Alumni | I8: Medical Technology | J8: Faculty Board (IDRP / AIIMS-IIT Joint) | K8: m20id005@iitj.ac.in | L8: - | M8: 0 | N8: - | O8: 0 | P8: - | Q8: 0 | R8: - | S8: 0 | T8: - | U8: - | V8: - | W8: Centre for Medical Technologies (IDRP) | X8: IIT Jodhpur Permanent Campus, NH 62, Karwar | Y8: Jodhpur | Z8: Rajasthan | AA8: 342030 | AB8: Official Cohort Registry (IIT Jodhpur MedTech Portal)
A9: 5 | B9: M20ID008 | C9: Thilak Chakaravarthi E | D9: Masters | E9: M.Tech in Medical Technology | F9: 2020 | G9: 2022 | H9: Alumni | I9: Electromechanical Cartilage Reshaping & Bio-MEMS | J9: Prof. Ajay Agarwal (IIT Jodhpur) | K9: m20id008@iitj.ac.in | L9: - | M9: 0 | N9: - | O9: 0 | P9: - | Q9: 1 | R9: Caldor Health Technologies Pvt. Ltd. (Co-Founder) | S9: 2 | T9: US$100,000 raised for SWASAM ; MSME grant | U9: - | V9: - | W9: Centre for Medical Technologies (IDRP) | X9: IIT Jodhpur Permanent Campus, NH 62, Karwar | Y9: Jodhpur | Z9: Rajasthan | AA9: 342030 | AB9: Official Cohort Registry (IIT Jodhpur MedTech Portal)
A10: 6 | B10: M20ID009 | C10: Rajshree | D10: Masters | E10: M.Tech in Medical Technology | F10: 2020 | G10: 2022 | H10: Alumni | I10: Medical Technology | J10: Faculty Board (IDRP / AIIMS-IIT Joint) | K10: m20id009@iitj.ac.in | L10: - | M10: 0 | N10: - | O10: 0 | P10: - | Q10: 0 | R10: - | S10: 0 | T10: - | U10: - | V10: - | W10: Centre for Medical Technologies (IDRP) | X10: IIT Jodhpur Permanent Campus, NH 62, Karwar | Y10: Jodhpur | Z10: Rajasthan | AA10: 342030 | AB10: Official Cohort Registry (IIT Jodhpur MedTech Portal)
A11: 7 | B11: P20ID002 | C11: Kanika Singroha | D11: PhD | E11: Ph.D. in Medical Technology | F11: 2020 | G11: 2025 | H11: Alumni | I11: 3D Bioprinting, Modular Bioinks & Regenerative Medicine | J11: Dr. Indranil Banerjee (IIT Jodhpur) & Dr. Shilpi Gupta Dixit (AIIMS Jodhpur) | K11: p20id002@iitj.ac.in | L11: - | M11: 0 | N11: - | O11: 1 | P11: App #202511037139: Quadruple High-Performance Modular Bioink for 3D Bioprinting (Filed) | Apps 202511037139, 202511037986: 3D Bioprinting Quadruple Modular Bioink & Cell Suspensor | Q11: 1 | R11: Cellverse Pvt. Ltd. (Co-Founder, Incubated) | Cellverse Pvt. Ltd. (Director & Co-Founder) | S11: 1 | T11: Recognition of Excellence in Young Alumni Award | U11: - | V11: - | W11: Centre for Medical Technologies (IDRP) | X11: IIT Jodhpur Permanent Campus, NH 62, Karwar | Y11: Jodhpur | Z11: Rajasthan | AA11: 342030 | AB11: Official Cohort Registry (IIT Jodhpur MedTech Portal)
A12: 8 | B12: P20ID003 | C12: Dushyant Agrawal | D12: PhD | E12: Ph.D. in Medical Technology | F12: 2020 | G12: 2025 | H12: Alumni | I12: Medical Technology | J12: Faculty Board (IDRP / AIIMS-IIT Joint) | K12: p20id003@iitj.ac.in | L12: - | M12: 0 | N12: - | O12: 0 | P12: - | Q12: 0 | R12: - | S12: 0 | T12: - | U12: - | V12: - | W12: Centre for Medical Technologies (IDRP) | X12: IIT Jodhpur Permanent Campus, NH 62, Karwar | Y12: Jodhpur | Z12: Rajasthan | AA12: 342030 | AB12: Official Cohort Registry (IIT Jodhpur MedTech Portal)
A13: 9 | B13: P20ID004 | C13: Gajendra Singh | D13: PhD | E13: Ph.D. in Medical Technology | F13: 2020 | G13: 2025 | H13: Alumni | I13: Medical Robotics, AI Echocardiography & Multimodal Data Sync | J13: Dr. Deepak Mishra (IIT Jodhpur) & Dr. Pushpinder Khera (AIIMS Jodhpur) | K13: singh.117@iitj.ac.in | L13: - | M13: 3 | N13: 1 Journals, 2 Conferences, 0 Books. Venues: 1. IEEE Sensor Letters 2. ASMUS MICCAI 2025 3. IEEE SAUS 2024 (First Author) | Paper: "Deep Learning-Driven Multimodal Synchronization for Probe-Navigated Echocardiography" | Paper: "ASMUS: Real-Time Point-of-Care Ultrasound Guidance via Multitask Acoustic Transformer" | Paper: "Acoustic Signal Processing and Robot Teleoperation for Pediatric Cardiac Ultrasound" | O13: 2 | P13: App #202211077085: System and Method for Robot Assisted Echocardiography (Published) | App #202411058458: System for Multimodal Data Acquisition and Synchronization and Method Thereof (Published) | Apps 202211077085, 202411058458, 202511040403: Robot Assisted Echocardiography & Multimodal Data Sync | Q13: 1 | R13: Visionence Tech Pvt. Ltd. (Co-Founder, Incubated) | Visionence Tech Pvt. Ltd. (Director & Co-Founder) | S13: 1 | T13: Patent granted | U13: - | V13: - | W13: Centre for Medical Technologies (IDRP) | X13: IIT Jodhpur Permanent Campus, NH 62, Karwar | Y13: Jodhpur | Z13: Rajasthan | AA13: 342030 | AB13: Official Cohort Registry (IIT Jodhpur MedTech Portal)
A14: 10 | B14: P20ID005 | C14: Mitanshu Sharma | D14: PhD | E14: Ph.D. in Medical Technology | F14: 2020 | G14: 2025 | H14: Alumni | I14: Assistive Critical Care & Pressure Ulcer Prevention | J14: Dr. Shobhana Singh (IIT Jodhpur) & Dr. Nikhil Kothari (AIIMS Jodhpur) | K14: p20id005@iitj.ac.in | L14: - | M14: 0 | N14: - | O14: 1 | P14: App #202211060577: Pressure Ulcers or Bed Sores Preventing Air Bubble Based Mattress (Published) | App 202211060577: Pressure Ulcers / Bed Sores Preventing Air Bubble Mattress | Q14: 0 | R14: - | S14: 0 | T14: - | U14: - | V14: - | W14: Centre for Medical Technologies (IDRP) | X14: IIT Jodhpur Permanent Campus, NH 62, Karwar | Y14: Jodhpur | Z14: Rajasthan | AA14: 342030 | AB14: Official Cohort Registry (IIT Jodhpur MedTech Portal)
A15: 11 | B15: P20ID006 | C15: Monika Sharma | D15: PhD | E15: Ph.D. in Medical Technology | F15: 2020 | G15: 2025 | H15: Alumni | I15: Neuromuscular Assessment & Force-Sensor Biomechanics | J15: Dr. Pankaj Yadav (IIT Jodhpur) | K15: p20id006@iitj.ac.in | L15: - | M15: 0 | N15: - | O15: 1 | P15: App 202511106532: Force-Sensor-Based Tapping Device for Neuromuscular Assessment | Q15: 0 | R15: - | S15: 1 | T15: IBRO Exchange Fellowship 2026 | U15: - | V15: - | W15: Centre for Medical Technologies (IDRP) | X15: IIT Jodhpur Permanent Campus, NH 62, Karwar | Y15: Jodhpur | Z15: Rajasthan | AA15: 342030 | AB15: Official Cohort Registry (IIT Jodhpur MedTech Portal)
A16: 12 | B16: P20ID007 | C16: Om Lata Bhagat | D16: PhD | E16: Ph.D. in Medical Technology | F16: 2020 | G16: 2025 | H16: Alumni | I16: Medical Technology | J16: Faculty Board (IDRP / AIIMS-IIT Joint) | K16: p20id007@iitj.ac.in | L16: - | M16: 0 | N16: - | O16: 0 | P16: - | Q16: 0 | R16: - | S16: 0 | T16: - | U16: - | V16: - | W16: Centre for Medical Technologies (IDRP) | X16: IIT Jodhpur Permanent Campus, NH 62, Karwar | Y16: Jodhpur | Z16: Rajasthan | AA16: 342030 | AB16: Official Cohort Registry (IIT Jodhpur MedTech Portal)
... A111: 107 | B111: P26IM0004 | C111: Saurabh Yadav | D111: PhD | E111: Ph.D. in Medical Technology | F111: 2026 | G111: 2031 | H111: Active | I111: Medical Technology | J111: Faculty Board (IDRP / AIIMS-IIT Joint) | K111: p26im0004@iitj.ac.in | L111: - | M111: 0 | N111: - | O111: 0 | P111: - | Q111: 0 | R111: - | S111: 0 | T111: - | U111: - | V111: - | W111: Centre for Medical Technologies (IDRP) | X111: IIT Jodhpur Permanent Campus, NH 62, Karwar | Y111: Jodhpur | Z111: Rajasthan | AA111: 342030 | AB111: Official Cohort Registry (IIT Jodhpur MedTech Portal)

Sheet M.Tech (Masters)
A1: CENTRE FOR MEDICAL TECHNOLOGIES (IDRP) | IIT JODHPUR & AIIMS JODHPUR
A2: M.Tech in Medical Technology — Complete Register of All 52 Masters Scholars (2020 – 2026 Batches)
A4: S.No. | B4: Roll Number | C4: Student Scholar Name | D4: Program Level | E4: Degree Program | F4: Cohort Year | G4: Graduation Year | H4: Academic Status | I4: Specialization & Research Focus | J4: Faculty Supervisor(s) (IIT & AIIMS) | K4: Institutional Email | L4: Contact Phone | M4: Publications (Count) | N4: Publication Venues & Papers | O4: Patents (Count) | P4: Patent Filings & Application Nos. | Q4: Startups (Count) | R4: Startup Ventures & Student Roles | S4: Awards (Count) | T4: Awards, Honors & Hackathon Wins | U4: Date of Birth | V4: Gender | W4: Department / Centre | X4: Campus / Residential Address | Y4: City | Z4: State | AA4: Pincode | AB4: Verification Source URL / Provenance
A5: 1 | B5: M20ID001 | C5: Anup Kamal Kakwani | D5: Masters | E5: M.Tech in Medical Technology | F5: 2020 | G5: 2022 | H5: Alumni | I5: Endodontics & Dental Irrigation Systems | J5: Dr. Pravin Kumar (AIIMS Jodhpur) & Dr. Jaiveer Singh (IIT Jodhpur) | K5: m20id001@iitj.ac.in | L5: - | M5: 0 | N5: - | O5: 1 | P5: App #202211041593: A Cost Effective and User Friendly System to Irrigate Root Canal Under Apical Negative Pressure (Published) | App 202211041593: Root Canal Irrigation System Under Apical Negative Pressure | Q5: 1 | R5: NxGen Healtech Pvt. Ltd. (Founder & Managing Director, Pre-Incubatee) | NxGen Healtech Pvt. Ltd. (Founder) | S5: 0 | T5: - | U5: - | V5: - | W5: Centre for Medical Technologies (IDRP) | X5: IIT Jodhpur Permanent Campus, NH 62, Karwar | Y5: Jodhpur | Z5: Rajasthan | AA5: 342030 | AB5: Official Cohort Registry (IIT Jodhpur MedTech Portal)
A6: 2 | B6: M20ID002 | C6: Anushri Bhardwaj | D6: Masters | E6: M.Tech in Medical Technology | F6: 2020 | G6: 2022 | H6: Alumni | I6: Medical Technology | J6: Faculty Board (IDRP / AIIMS-IIT Joint) | K6: m20id002@iitj.ac.in | L6: - | M6: 0 | N6: - | O6: 0 | P6: - | Q6: 0 | R6: - | S6: 0 | T6: - | U6: - | V6: - | W6: Centre for Medical Technologies (IDRP) | X6: IIT Jodhpur Permanent Campus, NH 62, Karwar | Y6: Jodhpur | Z6: Rajasthan | AA6: 342030 | AB6: Official Cohort Registry (IIT Jodhpur MedTech Portal)
A7: 3 | B7: M20ID004 | C7: Mridul Sharma | D7: Masters | E7: M.Tech in Medical Technology | F7: 2020 | G7: 2022 | H7: Alumni | I7: Medical Technology | J7: Faculty Board (IDRP / AIIMS-IIT Joint) | K7: m20id004@iitj.ac.in | L7: - | M7: 0 | N7: - | O7: 0 | P7: - | Q7: 0 | R7: - | S7: 0 | T7: - | U7: - | V7: - | W7: Centre for Medical Technologies (IDRP) | X7: IIT Jodhpur Permanent Campus, NH 62, Karwar | Y7: Jodhpur | Z7: Rajasthan | AA7: 342030 | AB7: Official Cohort Registry (IIT Jodhpur MedTech Portal)
A8: 4 | B8: M20ID005 | C8: Shradha Suman Panda | D8: Masters | E8: M.Tech in Medical Technology | F8: 2020 | G8: 2022 | H8: Alumni | I8: Medical Technology | J8: Faculty Board (IDRP / AIIMS-IIT Joint) | K8: m20id005@iitj.ac.in | L8: - | M8: 0 | N8: - | O8: 0 | P8: - | Q8: 0 | R8: - | S8: 0 | T8: - | U8: - | V8: - | W8: Centre for Medical Technologies (IDRP) | X8: IIT Jodhpur Permanent Campus, NH 62, Karwar | Y8: Jodhpur | Z8: Rajasthan | AA8: 342030 | AB8: Official Cohort Registry (IIT Jodhpur MedTech Portal)
A9: 5 | B9: M20ID008 | C9: Thilak Chakaravarthi E | D9: Masters | E9: M.Tech in Medical Technology | F9: 2020 | G9: 2022 | H9: Alumni | I9: Electromechanical Cartilage Reshaping & Bio-MEMS | J9: Prof. Ajay Agarwal (IIT Jodhpur) | K9: m20id008@iitj.ac.in | L9: - | M9: 0 | N9: - | O9: 0 | P9: - | Q9: 1 | R9: Caldor Health Technologies Pvt. Ltd. (Co-Founder) | S9: 2 | T9: US$100,000 raised for SWASAM ; MSME grant | U9: - | V9: - | W9: Centre for Medical Technologies (IDRP) | X9: IIT Jodhpur Permanent Campus, NH 62, Karwar | Y9: Jodhpur | Z9: Rajasthan | AA9: 342030 | AB9: Official Cohort Registry (IIT Jodhpur MedTech Portal)
A10: 6 | B10: M20ID009 | C10: Rajshree | D10: Masters | E10: M.Tech in Medical Technology | F10: 2020 | G10: 2022 | H10: Alumni | I10: Medical Technology | J10: Faculty Board (IDRP / AIIMS-IIT Joint) | K10: m20id009@iitj.ac.in | L10: - | M10: 0 | N10: - | O10: 0 | P10: - | Q10: 0 | R10: - | S10: 0 | T10: - | U10: - | V10: - | W10: Centre for Medical Technologies (IDRP) | X10: IIT Jodhpur Permanent Campus, NH 62, Karwar | Y10: Jodhpur | Z10: Rajasthan | AA10: 342030 | AB10: Official Cohort Registry (IIT Jodhpur MedTech Portal)
A11: 7 | B11: M21ID001 | C11: Ajisha Ck | D11: Masters | E11: M.Tech in Medical Technology | F11: 2021 | G11: 2023 | H11: Alumni | I11: Medical Technology | J11: Faculty Board (IDRP / AIIMS-IIT Joint) | K11: m21id001@iitj.ac.in | L11: - | M11: 0 | N11: - | O11: 0 | P11: - | Q11: 0 | R11: - | S11: 0 | T11: - | U11: - | V11: - | W11: Centre for Medical Technologies (IDRP) | X11: IIT Jodhpur Permanent Campus, NH 62, Karwar | Y11: Jodhpur | Z11: Rajasthan | AA11: 342030 | AB11: Official Cohort Registry (IIT Jodhpur MedTech Portal)
A12: 8 | B12: M21ID002 | C12: Ajmal Jaleel | D12: Masters | E12: M.Tech in Medical Technology | F12: 2021 | G12: 2023 | H12: Alumni | I12: Surgical Ergonomics & Mattress Hygiene Management Systems | J12: Dr. Jayant Kumar Mohanta (IIT Jodhpur) | K12: m21id002@iitj.ac.in | L12: - | M12: 0 | N12: - | O12: 0 | P12: - | Q12: 1 | R12: ShilpinMed Technologies Pvt. Ltd. (Founder) | S12: 0 | T12: - | U12: - | V12: - | W12: Centre for Medical Technologies (IDRP) | X12: IIT Jodhpur Permanent Campus, NH 62, Karwar | Y12: Jodhpur | Z12: Rajasthan | AA12: 342030 | AB12: Official Cohort Registry (IIT Jodhpur MedTech Portal)
A13: 9 | B13: M21ID003 | C13: Divesh Kumar Awasthi | D13: Masters | E13: M.Tech in Medical Technology | F13: 2021 | G13: 2023 | H13: Alumni | I13: Ultrasound-Guided Interventional Syringe Systems | J13: Dr. Hardik Kothadia (IIT Jodhpur) | K13: m21id003@iitj.ac.in | L13: - | M13: 0 | N13: - | O13: 0 | P13: - | Q13: 1 | R13: Healyantra Medical Technologies Pvt. Ltd. (Co-Founder) | S13: 2 | T13: First patent ; TechEx Technology Transfer Hub funding | U13: - | V13: - | W13: Centre for Medical Technologies (IDRP) | X13: IIT Jodhpur Permanent Campus, NH 62, Karwar | Y13: Jodhpur | Z13: Rajasthan | AA13: 342030 | AB13: Official Cohort Registry (IIT Jodhpur MedTech Portal)
A14: 10 | B14: M21ID004 | C14: Gaurav Sawriya | D14: Masters | E14: M.Tech in Medical Technology | F14: 2021 | G14: 2023 | H14: Alumni | I14: Medical Technology | J14: Faculty Board (IDRP / AIIMS-IIT Joint) | K14: m21id004@iitj.ac.in | L14: - | M14: 0 | N14: - | O14: 0 | P14: - | Q14: 0 | R14: - | S14: 0 | T14: - | U14: - | V14: - | W14: Centre for Medical Technologies (IDRP) | X14: IIT Jodhpur Permanent Campus, NH 62, Karwar | Y14: Jodhpur | Z14: Rajasthan | AA14: 342030 | AB14: Official Cohort Registry (IIT Jodhpur MedTech Portal)
A15: 11 | B15: M21ID005 | C15: Harisharan R | D15: Masters | E15: M.Tech in Medical Technology | F15: 2021 | G15: 2023 | H15: Alumni | I15: ENT Devices & Cartilage Reshaping Instrumentation | J15: Prof. Ajay Agarwal (IIT Jodhpur) & Dr. Amit Goyal (AIIMS Jodhpur) | K15: m21id005@iitj.ac.in | L15: - | M15: 0 | N15: - | O15: 1 | P15: App 202411033887: Device for Reshaping Cartilage | Q15: 1 | R15: Caldor Health Technologies Pvt. Ltd. (Co-Founder) | S15: 1 | T15: US$100,000 raised for SWASAM | U15: - | V15: - | W15: Centre for Medical Technologies (IDRP) | X15: IIT Jodhpur Permanent Campus, NH 62, Karwar | Y15: Jodhpur | Z15: Rajasthan | AA15: 342030 | AB15: Official Cohort Registry (IIT Jodhpur MedTech Portal)
A16: 12 | B16: M21ID007 | C16: Varun Raman Khandelwal | D16: Masters | E16: M.Tech in Medical Technology | F16: 2021 | G16: 2023 | H16: Alumni | I16: Ultrasound-Guided Surgical Procedures & Clinical Devices | J16: Dr. Hardik Kothadia (IIT Jodhpur) | K16: m21id007@iitj.ac.in | L16: - | M16: 0 | N16: - | O16: 0 | P16: - | Q16: 1 | R16: Healyantra Medical Technologies Pvt. Ltd. (Director & Co-Founder) | S16: 3 | T16: First patent ; TechEx Technology Transfer Hub funding ; Winner of MEDHA 2022 | U16: - | V16: - | W16: Centre for Medical Technologies (IDRP) | X16: IIT Jodhpur Permanent Campus, NH 62, Karwar | Y16: Jodhpur | Z16: Rajasthan | AA16: 342030 | AB16: Official Cohort Registry (IIT Jodhpur MedTech Portal)
... A56: 52 | B56: M26IM1009 | C56: Megha Bharadwaj | D56: Masters | E56: M.Tech in Medical Technology | F56: 2026 | G56: 2028 | H56: Active | I56: Medical Technology | J56: Faculty Board (IDRP / AIIMS-IIT Joint) | K56: m26im1009@iitj.ac.in | L56: - | M56: 0 | N56: - | O56: 0 | P56: - | Q56: 0 | R56: - | S56: 0 | T56: - | U56: - | V56: - | W56: Centre for Medical Technologies (IDRP) | X56: IIT Jodhpur Permanent Campus, NH 62, Karwar | Y56: Jodhpur | Z56: Rajasthan | AA56: 342030 | AB56: Official Cohort Registry (IIT Jodhpur MedTech Portal)

Sheet Ph.D. Scholars
A1: CENTRE FOR MEDICAL TECHNOLOGIES (IDRP) | IIT JODHPUR & AIIMS JODHPUR
A2: Doctoral Research Scholars (Ph.D.) — Complete Register of All 35 Ph.D. Scholars (2020 – 2026 Batches)
A4: S.No. | B4: Roll Number | C4: Student Scholar Name | D4: Program Level | E4: Degree Program | F4: Cohort Year | G4: Graduation Year | H4: Academic Status | I4: Specialization & Research Focus | J4: Faculty Supervisor(s) (IIT & AIIMS) | K4: Institutional Email | L4: Contact Phone | M4: Publications (Count) | N4: Publication Venues & Papers | O4: Patents (Count) | P4: Patent Filings & Application Nos. | Q4: Startups (Count) | R4: Startup Ventures & Student Roles | S4: Awards (Count) | T4: Awards, Honors & Hackathon Wins | U4: Date of Birth | V4: Gender | W4: Department / Centre | X4: Campus / Residential Address | Y4: City | Z4: State | AA4: Pincode | AB4: Verification Source URL / Provenance
A5: 1 | B5: P20ID002 | C5: Kanika Singroha | D5: PhD | E5: Ph.D. in Medical Technology | F5: 2020 | G5: 2025 | H5: Alumni | I5: 3D Bioprinting, Modular Bioinks & Regenerative Medicine | J5: Dr. Indranil Banerjee (IIT Jodhpur) & Dr. Shilpi Gupta Dixit (AIIMS Jodhpur) | K5: p20id002@iitj.ac.in | L5: - | M5: 0 | N5: - | O5: 1 | P5: App #202511037139: Quadruple High-Performance Modular Bioink for 3D Bioprinting (Filed) | Apps 202511037139, 202511037986: 3D Bioprinting Quadruple Modular Bioink & Cell Suspensor | Q5: 1 | R5: Cellverse Pvt. Ltd. (Co-Founder, Incubated) | Cellverse Pvt. Ltd. (Director & Co-Founder) | S5: 1 | T5: Recognition of Excellence in Young Alumni Award | U5: - | V5: - | W5: Centre for Medical Technologies (IDRP) | X5: IIT Jodhpur Permanent Campus, NH 62, Karwar | Y5: Jodhpur | Z5: Rajasthan | AA5: 342030 | AB5: Official Cohort Registry (IIT Jodhpur MedTech Portal)
A6: 2 | B6: P20ID003 | C6: Dushyant Agrawal | D6: PhD | E6: Ph.D. in Medical Technology | F6: 2020 | G6: 2025 | H6: Alumni | I6: Medical Technology | J6: Faculty Board (IDRP / AIIMS-IIT Joint) | K6: p20id003@iitj.ac.in | L6: - | M6: 0 | N6: - | O6: 0 | P6: - | Q6: 0 | R6: - | S6: 0 | T6: - | U6: - | V6: - | W6: Centre for Medical Technologies (IDRP) | X6: IIT Jodhpur Permanent Campus, NH 62, Karwar | Y6: Jodhpur | Z6: Rajasthan | AA6: 342030 | AB6: Official Cohort Registry (IIT Jodhpur MedTech Portal)
A7: 3 | B7: P20ID004 | C7: Gajendra Singh | D7: PhD | E7: Ph.D. in Medical Technology | F7: 2020 | G7: 2025 | H7: Alumni | I7: Medical Robotics, AI Echocardiography & Multimodal Data Sync | J7: Dr. Deepak Mishra (IIT Jodhpur) & Dr. Pushpinder Khera (AIIMS Jodhpur) | K7: singh.117@iitj.ac.in | L7: - | M7: 3 | N7: 1 Journals, 2 Conferences, 0 Books. Venues: 1. IEEE Sensor Letters 2. ASMUS MICCAI 2025 3. IEEE SAUS 2024 (First Author) | Paper: "Deep Learning-Driven Multimodal Synchronization for Probe-Navigated Echocardiography" | Paper: "ASMUS: Real-Time Point-of-Care Ultrasound Guidance via Multitask Acoustic Transformer" | Paper: "Acoustic Signal Processing and Robot Teleoperation for Pediatric Cardiac Ultrasound" | O7: 2 | P7: App #202211077085: System and Method for Robot Assisted Echocardiography (Published) | App #202411058458: System for Multimodal Data Acquisition and Synchronization and Method Thereof (Published) | Apps 202211077085, 202411058458, 202511040403: Robot Assisted Echocardiography & Multimodal Data Sync | Q7: 1 | R7: Visionence Tech Pvt. Ltd. (Co-Founder, Incubated) | Visionence Tech Pvt. Ltd. (Director & Co-Founder) | S7: 1 | T7: Patent granted | U7: - | V7: - | W7: Centre for Medical Technologies (IDRP) | X7: IIT Jodhpur Permanent Campus, NH 62, Karwar | Y7: Jodhpur | Z7: Rajasthan | AA7: 342030 | AB7: Official Cohort Registry (IIT Jodhpur MedTech Portal)
A8: 4 | B8: P20ID005 | C8: Mitanshu Sharma | D8: PhD | E8: Ph.D. in Medical Technology | F8: 2020 | G8: 2025 | H8: Alumni | I8: Assistive Critical Care & Pressure Ulcer Prevention | J8: Dr. Shobhana Singh (IIT Jodhpur) & Dr. Nikhil Kothari (AIIMS Jodhpur) | K8: p20id005@iitj.ac.in | L8: - | M8: 0 | N8: - | O8: 1 | P8: App #202211060577: Pressure Ulcers or Bed Sores Preventing Air Bubble Based Mattress (Published) | App 202211060577: Pressure Ulcers / Bed Sores Preventing Air Bubble Mattress | Q8: 0 | R8: - | S8: 0 | T8: - | U8: - | V8: - | W8: Centre for Medical Technologies (IDRP) | X8: IIT Jodhpur Permanent Campus, NH 62, Karwar | Y8: Jodhpur | Z8: Rajasthan | AA8: 342030 | AB8: Official Cohort Registry (IIT Jodhpur MedTech Portal)
A9: 5 | B9: P20ID006 | C9: Monika Sharma | D9: PhD | E9: Ph.D. in Medical Technology | F9: 2020 | G9: 2025 | H9: Alumni | I9: Neuromuscular Assessment & Force-Sensor Biomechanics | J9: Dr. Pankaj Yadav (IIT Jodhpur) | K9: p20id006@iitj.ac.in | L9: - | M9: 0 | N9: - | O9: 1 | P9: App 202511106532: Force-Sensor-Based Tapping Device for Neuromuscular Assessment | Q9: 0 | R9: - | S9: 1 | T9: IBRO Exchange Fellowship 2026 | U9: - | V9: - | W9: Centre for Medical Technologies (IDRP) | X9: IIT Jodhpur Permanent Campus, NH 62, Karwar | Y9: Jodhpur | Z9: Rajasthan | AA9: 342030 | AB9: Official Cohort Registry (IIT Jodhpur MedTech Portal)
A10: 6 | B10: P20ID007 | C10: Om Lata Bhagat | D10: PhD | E10: Ph.D. in Medical Technology | F10: 2020 | G10: 2025 | H10: Alumni | I10: Medical Technology | J10: Faculty Board (IDRP / AIIMS-IIT Joint) | K10: p20id007@iitj.ac.in | L10: - | M10: 0 | N10: - | O10: 0 | P10: - | Q10: 0 | R10: - | S10: 0 | T10: - | U10: - | V10: - | W10: Centre for Medical Technologies (IDRP) | X10: IIT Jodhpur Permanent Campus, NH 62, Karwar | Y10: Jodhpur | Z10: Rajasthan | AA10: 342030 | AB10: Official Cohort Registry (IIT Jodhpur MedTech Portal)
A11: 7 | B11: P20ID009 | C11: Sakshi Malik | D11: PhD | E11: Ph.D. in Medical Technology | F11: 2020 | G11: 2025 | H11: Alumni | I11: Medical Technology | J11: Faculty Board (IDRP / AIIMS-IIT Joint) | K11: p20id009@iitj.ac.in | L11: - | M11: 0 | N11: - | O11: 0 | P11: - | Q11: 0 | R11: - | S11: 0 | T11: - | U11: - | V11: - | W11: Centre for Medical Technologies (IDRP) | X11: IIT Jodhpur Permanent Campus, NH 62, Karwar | Y11: Jodhpur | Z11: Rajasthan | AA11: 342030 | AB11: Official Cohort Registry (IIT Jodhpur MedTech Portal)
A12: 8 | B12: P20ID010 | C12: Sudesh Pachar | D12: PhD | E12: Ph.D. in Medical Technology | F12: 2020 | G12: 2025 | H12: Alumni | I12: Medical Technology | J12: Faculty Board (IDRP / AIIMS-IIT Joint) | K12: p20id010@iitj.ac.in | L12: - | M12: 0 | N12: - | O12: 0 | P12: - | Q12: 0 | R12: - | S12: 0 | T12: - | U12: - | V12: - | W12: Centre for Medical Technologies (IDRP) | X12: IIT Jodhpur Permanent Campus, NH 62, Karwar | Y12: Jodhpur | Z12: Rajasthan | AA12: 342030 | AB12: Official Cohort Registry (IIT Jodhpur MedTech Portal)
A13: 9 | B13: P20SH002 | C13: Netra Kirankumar Hiremath | D13: PhD | E13: Ph.D. in Medical Technology | F13: 2020 | G13: 2025 | H13: Active | I13: Nanomedicine & Biomaterials Science | J13: Faculty Board (IDRP / School of Health) | K13: hiremath.1@iitj.ac.in | L13: +91 97840 55667 | M13: 6 | N13: 6 Journals, 0 Conferences, 0 Books. Venues: 1. ACS Applied Nano Materials (2 publications) 2. Biomaterials Science (2 publications) 3. Nanoscale 4. ChemMedChem (Co-Author) | O13: 0 | P13: - | Q13: 0 | R13: - | S13: 0 | T13: - | U13: 1996-03-14 | V13: Female | W13: Centre for Medical Technologies (IDRP) | X13: IIT Jodhpur Campus | Y13: Jodhpur | Z13: Rajasthan | AA13: 342030 | AB13: Centre for Medical Technologies Seed Registry
A14: 10 | B14: P20SH003 | C14: Nikhil Vadera | D14: PhD | E14: Ph.D. in Medical Technology | F14: 2020 | G14: 2025 | H14: Active | I14: Electrochemical Biosensors & Chemical Sensing | J14: Faculty Board (IDRP / School of Health) | K14: vadera.1@iitj.ac.in | L14: +91 98290 11223 | M14: 5 | N14: 3 Journals, 2 Conferences, 0 Books. Venues: 1. Microchemical Journal 2. ACS Sensors Journal 3. IEEE Sensors Letters Journal 4. IEEE APSCON Conference 5. IEEE Sensors Conference (First Author) | O14: 0 | P14: - | Q14: 0 | R14: - | S14: 0 | T14: - | U14: 1996-08-20 | V14: Male | W14: Centre for Medical Technologies (IDRP) | X14: IIT Jodhpur Campus | Y14: Jodhpur | Z14: Rajasthan | AA14: 342030 | AB14: Centre for Medical Technologies Seed Registry
A15: 11 | B15: P20SH004 | C15: Ritesh Mishra | D15: PhD | E15: Ph.D. in Medical Technology | F15: 2020 | G15: 2025 | H15: Active | I15: Plasma Medicine & Agro-Food Quality Diagnostics | J15: Faculty Board (IDRP / School of Health) | K15: mishra.15@iitj.ac.in | L15: +91 94140 33445 | M15: 8 | N15: 6 Journals, 1 Conferences, 1 Books. Venues: 1. Food Control 2. RSC Sustainable Food Technology 3. Irrigation Science 4. Postharvest Biology and Technology 5. Reviews of Modern Plasma Physics 6. Radiation Effects and Defects in Solids (First Author) | O15: 0 | P15: - | Q15: 0 | R15: - | S15: 0 | T15: - | U15: 1995-11-12 | V15: Male | W15: Centre for Medical Technologies (IDRP) | X15: IIT Jodhpur Campus | Y15: Jodhpur | Z15: Rajasthan | AA15: 342030 | AB15: Centre for Medical Technologies Seed Registry
A16: 12 | B16: IDRPSHC006 | C16: Ramkamal samat | D16: PhD | E16: Ph.D. in Medical Technology | F16: 2021 | G16: 2026 | H16: Alumni | I16: Medicinal Chemistry & Infectious Disease Therapeutics | J16: Faculty Board (IDRP / School of Health) | K16: samat.1@iitj.ac.in | L16: - | M16: 4 | N16: 4 Journals, 0 Conferences, 0 Books. Venues: Acs infectious disease, Journal of Medicinal chemistry (First Author) | O16: 0 | P16: - | Q16: 0 | R16: - | S16: 0 | T16: - | U16: - | V16: - | W16: Centre for Medical Technologies (IDRP / School of Health) | X16: IIT Jodhpur Permanent Campus, NH 62, Karwar | Y16: Jodhpur | Z16: Rajasthan | AA16: 342030 | AB16: Centre Verified Research Publication Submission
... A39: 35 | B39: P26IM0004 | C39: Saurabh Yadav | D39: PhD | E39: Ph.D. in Medical Technology | F39: 2026 | G39: 2031 | H39: Active | I39: Medical Technology | J39: Faculty Board (IDRP / AIIMS-IIT Joint) | K39: p26im0004@iitj.ac.in | L39: - | M39: 0 | N39: - | O39: 0 | P39: - | Q39: 0 | R39: - | S39: 0 | T39: - | U39: - | V39: - | W39: Centre for Medical Technologies (IDRP) | X39: IIT Jodhpur Permanent Campus, NH 62, Karwar | Y39: Jodhpur | Z39: Rajasthan | AA39: 342030 | AB39: Official Cohort Registry (IIT Jodhpur MedTech Portal)

Sheet Dual Degree (M.Tech-Ph.D.)
A1: CENTRE FOR MEDICAL TECHNOLOGIES (IDRP) | IIT JODHPUR & AIIMS JODHPUR
A2: M.Tech-Ph.D. Dual Degree in Medical Technology — Complete Register of All 20 Scholars (2020 – 2025 Batches)
A4: S.No. | B4: Roll Number | C4: Student Scholar Name | D4: Program Level | E4: Degree Program | F4: Cohort Year | G4: Graduation Year | H4: Academic Status | I4: Specialization & Research Focus | J4: Faculty Supervisor(s) (IIT & AIIMS) | K4: Institutional Email | L4: Contact Phone | M4: Publications (Count) | N4: Publication Venues & Papers | O4: Patents (Count) | P4: Patent Filings & Application Nos. | Q4: Startups (Count) | R4: Startup Ventures & Student Roles | S4: Awards (Count) | T4: Awards, Honors & Hackathon Wins | U4: Date of Birth | V4: Gender | W4: Department / Centre | X4: Campus / Residential Address | Y4: City | Z4: State | AA4: Pincode | AB4: Verification Source URL / Provenance
A5: 1 | B5: D20ID001 | C5: Ramkishore Jangid | D5: Dual Degree | E5: M.Tech-Ph.D. Dual Degree in Medical Technology | F5: 2020 | G5: 2025 | H5: Alumni | I5: Endotracheal Instrumentation & Critical Care Devices | J5: Dr. Shobhana Singh (IIT Jodhpur) | K5: d20id001@iitj.ac.in | L5: - | M5: 0 | N5: - | O5: 0 | P5: - | Q5: 1 | R5: Medvocare Pvt. Ltd. (Director & Co-Founder) | S5: 0 | T5: - | U5: - | V5: - | W5: Centre for Medical Technologies (IDRP) | X5: IIT Jodhpur Permanent Campus, NH 62, Karwar | Y5: Jodhpur | Z5: Rajasthan | AA5: 342030 | AB5: Official Cohort Registry (IIT Jodhpur MedTech Portal)
A6: 2 | B6: D20ID003 | C6: Justy N Francis | D6: Dual Degree | E6: M.Tech-Ph.D. Dual Degree in Medical Technology | F6: 2020 | G6: 2025 | H6: Alumni | I6: Osteogenic-Angiogenic Biomaterials & Craniofacial Implants | J6: Dr. Jaiveer Singh (IIT Jodhpur) & Dr. Ankita Chugh (AIIMS Jodhpur) | K6: francis.1@iitj.ac.in | L6: - | M6: 3 | N6: 3 Journals, 0 Conferences, 0 Books. Venues: Polymer Composites, Materials Chemistry and Physics (First Author) | Paper: "Bioactive Polymeric Composites for Craniofacial Fracture Fixation and Guided Tissue Regeneration" | O6: 1 | P6: App #202511040294: An Osteogenic-Angiogenic Composition and Implementations Thereof (Filed) | App 202511040294: Osteogenic-Angiogenic Implant Composition | Q6: 0 | R6: - | S6: 0 | T6: - | U6: - | V6: - | W6: Centre for Medical Technologies (IDRP) | X6: IIT Jodhpur Permanent Campus, NH 62, Karwar | Y6: Jodhpur | Z6: Rajasthan | AA6: 342030 | AB6: Official Cohort Registry (IIT Jodhpur MedTech Portal)
A7: 3 | B7: D20ID004 | C7: Misaal Khan | D7: Dual Degree | E7: M.Tech-Ph.D. Dual Degree in Medical Technology | F7: 2020 | G7: 2025 | H7: Alumni | I7: AI in Healthcare, Pediatric Malnutrition & Graph Neural Networks | J7: Prof. Richa Singh (IIT Jodhpur), Prof. Mayank Vatsa (IIT Jodhpur) & Dr. Kuldeep Singh (AIIMS Jodhpur) | K7: khan.9@iitj.ac.in | L7: +91 94140 82910 | M7: 6 | N7: 1 Journals, 4 Conferences, 1 Books. Venues: 1 . Frontiers in Public Health 2. IJCAI 2023 3. MICCAI 2024 4. AAAI 2026 5. WACV 2026 No book chapter (First Author) | Paper: "AI-Assisted Malnutrition and Pediatric Growth Deficit Assessment in Rural Cohorts: A Field-Validated Study" | Paper: "Deep Multi-View Graph Learning for Pediatric Anthropometry and Health Indices Prediction" | Paper: "Cross-Modality Contrastive Representation for 3D Pediatric Anthropometry from Single RGB-D Feeds" | Paper: "Generative Clinical Graph Networks for Undernutrition Surveillance in Low-Resource Primary Care" | Paper: "Self-Supervised Anatomical Landmark Estimation for Point-of-Care Child Stunting Diagnosis" | O7: 1 | P7: App #202511127461: System and Method for Assisting Malnutrition Assessment Using Graph Neural Networks (Published) | Apps 202411076128, 202511127461: AI Pediatric Nutritional Assessment System | Q7: 1 | R7: NutriAI HealthTech Solutions (Student Co-Founder & CTO, Pre-Incubatee) | NutriAI HealthTech Solutions (Student Co-Founder & CTO) | S7: 1 | T7: Prime Minister's Research Fellowship (PMRF) 2022 | U7: 1997-06-15 | V7: Male | W7: Centre for Medical Technologies (IDRP) | X7: Room 312, B3 Hostel, IIT Jodhpur Permanent Campus, NH 62 | Y7: Jodhpur | Z7: Rajasthan | AA7: 342030 | AB7: Official Cohort Registry (IIT Jodhpur MedTech Portal)
A8: 4 | B8: D20ID005 | C8: Neha Nagarkoti | D8: Dual Degree | E8: M.Tech-Ph.D. Dual Degree in Medical Technology | F8: 2020 | G8: 2025 | H8: Alumni | I8: Neonatal Transport Incubators & Thermal Regulation Systems | J8: Dr. Kaushal A. Desai (IIT Jodhpur) & Dr. Neeraj Gupta (AIIMS Jodhpur) | K8: d20id005@iitj.ac.in | L8: - | M8: 0 | N8: - | O8: 1 | P8: App 202511107337: Neonatal Thermal Regulation System & Transport Incubator | Q8: 0 | R8: - | S8: 2 | T8: ANRF Maha MedTech Mission grant ; BIRAC BIG grant | U8: - | V8: - | W8: Centre for Medical Technologies (IDRP) | X8: IIT Jodhpur Permanent Campus, NH 62, Karwar | Y8: Jodhpur | Z8: Rajasthan | AA8: 342030 | AB8: Official Cohort Registry (IIT Jodhpur MedTech Portal)
A9: 5 | B9: D20ID006 | C9: Saloni Singhal | D9: Dual Degree | E9: M.Tech-Ph.D. Dual Degree in Medical Technology | F9: 2020 | G9: 2025 | H9: Alumni | I9: Paper-Based Analytical Devices (PADs) & Glucose Biosensors | J9: Dr. Ankur Gupta (IIT Jodhpur) & Dr. Saptarshi Mandal (AIIMS Jodhpur) | K9: d20id006@iitj.ac.in | L9: - | M9: 0 | N9: - | O9: 1 | P9: App #202511116826: A Paper-Based Analytical Device (PAD) for Blood Typing and Method Thereof (Filed) | Apps 202511041154 (Granted), 202511046430 (Granted), 202511064909 (Granted), 202511072465, 202511116826: Paper-Based Biosensors & Hematocrit Diagnostic Devices | Q9: 0 | R9: - | S9: 1 | T9: Indian patent granted | U9: - | V9: - | W9: Centre for Medical Technologies (IDRP) | X9: IIT Jodhpur Permanent Campus, NH 62, Karwar | Y9: Jodhpur | Z9: Rajasthan | AA9: 342030 | AB9: Official Cohort Registry (IIT Jodhpur MedTech Portal)
A10: 6 | B10: D20ID007 | C10: Sambit Kumar Keshi | D10: Dual Degree | E10: M.Tech-Ph.D. Dual Degree in Medical Technology | F10: 2020 | G10: 2025 | H10: Alumni | I10: Acoustic Sensors & Kavak Sensorium Diagnostics | J10: Prof. Ajay Agarwal (IIT Jodhpur) | K10: d20id007@iitj.ac.in | L10: - | M10: 0 | N10: - | O10: 0 | P10: - | Q10: 1 | R10: Sarbit Innovations Pvt. Ltd. (Director & Co-Founder) | S10: 2 | T10: Arohan 5.0 seed support scheme ; MSME Idea Hackathon 4.0 grants | U10: - | V10: - | W10: Centre for Medical Technologies (IDRP) | X10: IIT Jodhpur Permanent Campus, NH 62, Karwar | Y10: Jodhpur | Z10: Rajasthan | AA10: 342030 | AB10: Official Cohort Registry (IIT Jodhpur MedTech Portal)
A11: 7 | B11: D20ID008 | C11: Sarmistha Mazumder | D11: Dual Degree | E11: M.Tech-Ph.D. Dual Degree in Medical Technology | F11: 2020 | G11: 2025 | H11: Alumni | I11: NIR Light-Activatable Biomimetic Phototherapy Systems | J11: Dr. Raviraj Vankayala (IIT Jodhpur) | K11: mazumder.3@iitj.ac.in | L11: - | M11: 7 | N11: 5 Journals, 0 Conferences, 2 Books. Venues: Frontiers in Chemistry, RSC advances, ACS ES&T Water, Chemistry- An Asian Journal, ACS Applied Nanomaterials Elsevier (Book chapters) (First Author) | Paper: "Near-Infrared Light-Triggered Nanoplatform for Targeted Tumor Photothermal Ablation" | O11: 1 | P11: App #202511113643: Near Infrared Light Activatable Biomimetic Drug Delivery System for Targeted Phototherapy (Filed) | App 202511113643: Near Infrared Light Activatable Biomimetic Phototherapy System | Q11: 0 | R11: - | S11: 0 | T11: - | U11: - | V11: - | W11: Centre for Medical Technologies (IDRP) | X11: IIT Jodhpur Permanent Campus, NH 62, Karwar | Y11: Jodhpur | Z11: Rajasthan | AA11: 342030 | AB11: Official Cohort Registry (IIT Jodhpur MedTech Portal)
A12: 8 | B12: D20ID009 | C12: Yashraj Singh | D12: Dual Degree | E12: M.Tech-Ph.D. Dual Degree in Medical Technology | F12: 2020 | G12: 2025 | H12: Alumni | I12: Medical Technology | J12: Faculty Board (IDRP / AIIMS-IIT Joint) | K12: d20id009@iitj.ac.in | L12: - | M12: 0 | N12: - | O12: 0 | P12: - | Q12: 0 | R12: - | S12: 0 | T12: - | U12: - | V12: - | W12: Centre for Medical Technologies (IDRP) | X12: IIT Jodhpur Permanent Campus, NH 62, Karwar | Y12: Jodhpur | Z12: Rajasthan | AA12: 342030 | AB12: Official Cohort Registry (IIT Jodhpur MedTech Portal)
A13: 9 | B13: D21ID003 | C13: Manik Sejwal | D13: Dual Degree | E13: M.Tech-Ph.D. Dual Degree in Medical Technology | F13: 2021 | G13: 2026 | H13: Alumni | I13: Medical Technology | J13: Faculty Board (IDRP / AIIMS-IIT Joint) | K13: d21id003@iitj.ac.in | L13: - | M13: 0 | N13: - | O13: 0 | P13: - | Q13: 0 | R13: - | S13: 0 | T13: - | U13: - | V13: - | W13: Centre for Medical Technologies (IDRP) | X13: IIT Jodhpur Permanent Campus, NH 62, Karwar | Y13: Jodhpur | Z13: Rajasthan | AA13: 342030 | AB13: Official Cohort Registry (IIT Jodhpur MedTech Portal)
A14: 10 | B14: D21ID004 | C14: Ravi Singhal | D14: Dual Degree | E14: M.Tech-Ph.D. Dual Degree in Medical Technology | F14: 2021 | G14: 2026 | H14: Alumni | I14: Medical Technology | J14: Faculty Board (IDRP / AIIMS-IIT Joint) | K14: d21id004@iitj.ac.in | L14: - | M14: 0 | N14: - | O14: 0 | P14: - | Q14: 0 | R14: - | S14: 0 | T14: - | U14: - | V14: - | W14: Centre for Medical Technologies (IDRP) | X14: IIT Jodhpur Permanent Campus, NH 62, Karwar | Y14: Jodhpur | Z14: Rajasthan | AA14: 342030 | AB14: Official Cohort Registry (IIT Jodhpur MedTech Portal)
A15: 11 | B15: D21ID005 | C15: Sayak Sarkar | D15: Dual Degree | E15: M.Tech-Ph.D. Dual Degree in Medical Technology | F15: 2021 | G15: 2026 | H15: Alumni | I15: Medical Technology | J15: Faculty Board (IDRP / AIIMS-IIT Joint) | K15: d21id005@iitj.ac.in | L15: - | M15: 0 | N15: - | O15: 0 | P15: - | Q15: 0 | R15: - | S15: 2 | T15: First patent ; TechEx Technology Transfer Hub funding | U15: - | V15: - | W15: Centre for Medical Technologies (IDRP) | X15: IIT Jodhpur Permanent Campus, NH 62, Karwar | Y15: Jodhpur | Z15: Rajasthan | AA15: 342030 | AB15: Official Cohort Registry (IIT Jodhpur MedTech Portal)
A16: 12 | B16: D21ID006 | C16: Katyayanee Sharma | D16: Dual Degree | E16: M.Tech-Ph.D. Dual Degree in Medical Technology | F16: 2021 | G16: 2026 | H16: Active | I16: Nano-Electronic Sensors & Surgical Reshaping Devices | J16: Prof. Ajay Agarwal (IIT Jodhpur) | K16: sharma.108@iitj.ac.in | L16: +91 94140 11223 | M16: 3 | N16: 1 Journals, 1 Conferences, 1 Books. Venues: 1. Conference- MNDCS 2024 2. Chapter- Lecture Notes in Electrical Engineering, vol 1382. Springer 3. Chapter- IEEE Biosensors (under review) (First Author) | Paper: "Ultra-Low Power CMOS Transceiver for Implantable Bio-Telemetry Sensors" | O16: 1 | P16: App 202411033887: Device for Reshaping Cartilage | Q16: 0 | R16: - | S16: 1 | T16: MSME Idea Hackathon 4.0 grants | U16: 1997-09-30 | V16: Female | W16: Centre for Medical Technologies (IDRP) | X16: Ph.D. Scholar Block C, Room 218, IIT Jodhpur | Y16: Jodhpur | Z16: Rajasthan | AA16: 342030 | AB16: Official Cohort Registry (IIT Jodhpur MedTech Portal)
... A24: 20 | B24: D25IM1005 | C24: Mohammed Fahim C | D24: Dual Degree | E24: M.Tech-Ph.D. Dual Degree in Medical Technology | F24: 2025 | G24: 2030 | H24: Active | I24: Medical Technology | J24: Faculty Board (IDRP / AIIMS-IIT Joint) | K24: d25im1005@iitj.ac.in | L24: - | M24: 0 | N24: - | O24: 0 | P24: - | Q24: 0 | R24: - | S24: 0 | T24: - | U24: - | V24: - | W24: Centre for Medical Technologies (IDRP) | X24: IIT Jodhpur Permanent Campus, NH 62, Karwar | Y24: Jodhpur | Z24: Rajasthan | AA24: 342030 | AB24: Official Cohort Registry (IIT Jodhpur MedTech Portal)

Sheet Year-Wise Cohorts
A1: CENTRE FOR MEDICAL TECHNOLOGIES (IDRP) | IIT JODHPUR & AIIMS JODHPUR
A2: Chronological Year-by-Year Cohort Register (2020 through 2026 Admissions)
A4: 🎓 ADMISSION COHORT 2020 — Total Scholars: 25 (Masters: 6 | Ph.D.: 11 | Dual Degree: 8)
A5: S.No. | B5: Roll Number | C5: Student Scholar Name | D5: Program Level | E5: Degree Program | F5: Cohort Year | G5: Graduation Year | H5: Academic Status | I5: Specialization & Research Focus | J5: Faculty Supervisor(s) (IIT & AIIMS) | K5: Institutional Email | L5: Contact Phone | M5: Publications (Count) | N5: Publication Venues & Papers | O5: Patents (Count) | P5: Patent Filings & Application Nos. | Q5: Startups (Count) | R5: Startup Ventures & Student Roles | S5: Awards (Count) | T5: Awards, Honors & Hackathon Wins | U5: Date of Birth | V5: Gender | W5: Department / Centre | X5: Campus / Residential Address | Y5: City | Z5: State | AA5: Pincode | AB5: Verification Source URL / Provenance
A6: 1 | B6: M20ID001 | C6: Anup Kamal Kakwani | D6: Masters | E6: M.Tech in Medical Technology | F6: 2020 | G6: 2022 | H6: Alumni | I6: Endodontics & Dental Irrigation Systems | J6: Dr. Pravin Kumar (AIIMS Jodhpur) & Dr. Jaiveer Singh (IIT Jodhpur) | K6: m20id001@iitj.ac.in | L6: - | M6: 0 | N6: - | O6: 1 | P6: App #202211041593: A Cost Effective and User Friendly System to Irrigate Root Canal Under Apical Negative Pressure (Published) | App 202211041593: Root Canal Irrigation System Under Apical Negative Pressure | Q6: 1 | R6: NxGen Healtech Pvt. Ltd. (Founder & Managing Director, Pre-Incubatee) | NxGen Healtech Pvt. Ltd. (Founder) | S6: 0 | T6: - | U6: - | V6: - | W6: Centre for Medical Technologies (IDRP) | X6: IIT Jodhpur Permanent Campus, NH 62, Karwar | Y6: Jodhpur | Z6: Rajasthan | AA6: 342030 | AB6: Official Cohort Registry (IIT Jodhpur MedTech Portal)
A7: 2 | B7: M20ID002 | C7: Anushri Bhardwaj | D7: Masters | E7: M.Tech in Medical Technology | F7: 2020 | G7: 2022 | H7: Alumni | I7: Medical Technology | J7: Faculty Board (IDRP / AIIMS-IIT Joint) | K7: m20id002@iitj.ac.in | L7: - | M7: 0 | N7: - | O7: 0 | P7: - | Q7: 0 | R7: - | S7: 0 | T7: - | U7: - | V7: - | W7: Centre for Medical Technologies (IDRP) | X7: IIT Jodhpur Permanent Campus, NH 62, Karwar | Y7: Jodhpur | Z7: Rajasthan | AA7: 342030 | AB7: Official Cohort Registry (IIT Jodhpur MedTech Portal)
A8: 3 | B8: M20ID004 | C8: Mridul Sharma | D8: Masters | E8: M.Tech in Medical Technology | F8: 2020 | G8: 2022 | H8: Alumni | I8: Medical Technology | J8: Faculty Board (IDRP / AIIMS-IIT Joint) | K8: m20id004@iitj.ac.in | L8: - | M8: 0 | N8: - | O8: 0 | P8: - | Q8: 0 | R8: - | S8: 0 | T8: - | U8: - | V8: - | W8: Centre for Medical Technologies (IDRP) | X8: IIT Jodhpur Permanent Campus, NH 62, Karwar | Y8: Jodhpur | Z8: Rajasthan | AA8: 342030 | AB8: Official Cohort Registry (IIT Jodhpur MedTech Portal)
A9: 4 | B9: M20ID005 | C9: Shradha Suman Panda | D9: Masters | E9: M.Tech in Medical Technology | F9: 2020 | G9: 2022 | H9: Alumni | I9: Medical Technology | J9: Faculty Board (IDRP / AIIMS-IIT Joint) | K9: m20id005@iitj.ac.in | L9: - | M9: 0 | N9: - | O9: 0 | P9: - | Q9: 0 | R9: - | S9: 0 | T9: - | U9: - | V9: - | W9: Centre for Medical Technologies (IDRP) | X9: IIT Jodhpur Permanent Campus, NH 62, Karwar | Y9: Jodhpur | Z9: Rajasthan | AA9: 342030 | AB9: Official Cohort Registry (IIT Jodhpur MedTech Portal)
A10: 5 | B10: M20ID008 | C10: Thilak Chakaravarthi E | D10: Masters | E10: M.Tech in Medical Technology | F10: 2020 | G10: 2022 | H10: Alumni | I10: Electromechanical Cartilage Reshaping & Bio-MEMS | J10: Prof. Ajay Agarwal (IIT Jodhpur) | K10: m20id008@iitj.ac.in | L10: - | M10: 0 | N10: - | O10: 0 | P10: - | Q10: 1 | R10: Caldor Health Technologies Pvt. Ltd. (Co-Founder) | S10: 2 | T10: US$100,000 raised for SWASAM ; MSME grant | U10: - | V10: - | W10: Centre for Medical Technologies (IDRP) | X10: IIT Jodhpur Permanent Campus, NH 62, Karwar | Y10: Jodhpur | Z10: Rajasthan | AA10: 342030 | AB10: Official Cohort Registry (IIT Jodhpur MedTech Portal)
A11: 6 | B11: M20ID009 | C11: Rajshree | D11: Masters | E11: M.Tech in Medical Technology | F11: 2020 | G11: 2022 | H11: Alumni | I11: Medical Technology | J11: Faculty Board (IDRP / AIIMS-IIT Joint) | K11: m20id009@iitj.ac.in | L11: - | M11: 0 | N11: - | O11: 0 | P11: - | Q11: 0 | R11: - | S11: 0 | T11: - | U11: - | V11: - | W11: Centre for Medical Technologies (IDRP) | X11: IIT Jodhpur Permanent Campus, NH 62, Karwar | Y11: Jodhpur | Z11: Rajasthan | AA11: 342030 | AB11: Official Cohort Registry (IIT Jodhpur MedTech Portal)
A12: 7 | B12: P20ID002 | C12: Kanika Singroha | D12: PhD | E12: Ph.D. in Medical Technology | F12: 2020 | G12: 2025 | H12: Alumni | I12: 3D Bioprinting, Modular Bioinks & Regenerative Medicine | J12: Dr. Indranil Banerjee (IIT Jodhpur) & Dr. Shilpi Gupta Dixit (AIIMS Jodhpur) | K12: p20id002@iitj.ac.in | L12: - | M12: 0 | N12: - | O12: 1 | P12: App #202511037139: Quadruple High-Performance Modular Bioink for 3D Bioprinting (Filed) | Apps 202511037139, 202511037986: 3D Bioprinting Quadruple Modular Bioink & Cell Suspensor | Q12: 1 | R12: Cellverse Pvt. Ltd. (Co-Founder, Incubated) | Cellverse Pvt. Ltd. (Director & Co-Founder) | S12: 1 | T12: Recognition of Excellence in Young Alumni Award | U12: - | V12: - | W12: Centre for Medical Technologies (IDRP) | X12: IIT Jodhpur Permanent Campus, NH 62, Karwar | Y12: Jodhpur | Z12: Rajasthan | AA12: 342030 | AB12: Official Cohort Registry (IIT Jodhpur MedTech Portal)
A13: 8 | B13: P20ID003 | C13: Dushyant Agrawal | D13: PhD | E13: Ph.D. in Medical Technology | F13: 2020 | G13: 2025 | H13: Alumni | I13: Medical Technology | J13: Faculty Board (IDRP / AIIMS-IIT Joint) | K13: p20id003@iitj.ac.in | L13: - | M13: 0 | N13: - | O13: 0 | P13: - | Q13: 0 | R13: - | S13: 0 | T13: - | U13: - | V13: - | W13: Centre for Medical Technologies (IDRP) | X13: IIT Jodhpur Permanent Campus, NH 62, Karwar | Y13: Jodhpur | Z13: Rajasthan | AA13: 342030 | AB13: Official Cohort Registry (IIT Jodhpur MedTech Portal)
A14: 9 | B14: P20ID004 | C14: Gajendra Singh | D14: PhD | E14: Ph.D. in Medical Technology | F14: 2020 | G14: 2025 | H14: Alumni | I14: Medical Robotics, AI Echocardiography & Multimodal Data Sync | J14: Dr. Deepak Mishra (IIT Jodhpur) & Dr. Pushpinder Khera (AIIMS Jodhpur) | K14: singh.117@iitj.ac.in | L14: - | M14: 3 | N14: 1 Journals, 2 Conferences, 0 Books. Venues: 1. IEEE Sensor Letters 2. ASMUS MICCAI 2025 3. IEEE SAUS 2024 (First Author) | Paper: "Deep Learning-Driven Multimodal Synchronization for Probe-Navigated Echocardiography" | Paper: "ASMUS: Real-Time Point-of-Care Ultrasound Guidance via Multitask Acoustic Transformer" | Paper: "Acoustic Signal Processing and Robot Teleoperation for Pediatric Cardiac Ultrasound" | O14: 2 | P14: App #202211077085: System and Method for Robot Assisted Echocardiography (Published) | App #202411058458: System for Multimodal Data Acquisition and Synchronization and Method Thereof (Published) | Apps 202211077085, 202411058458, 202511040403: Robot Assisted Echocardiography & Multimodal Data Sync | Q14: 1 | R14: Visionence Tech Pvt. Ltd. (Co-Founder, Incubated) | Visionence Tech Pvt. Ltd. (Director & Co-Founder) | S14: 1 | T14: Patent granted | U14: - | V14: - | W14: Centre for Medical Technologies (IDRP) | X14: IIT Jodhpur Permanent Campus, NH 62, Karwar | Y14: Jodhpur | Z14: Rajasthan | AA14: 342030 | AB14: Official Cohort Registry (IIT Jodhpur MedTech Portal)
A15: 10 | B15: P20ID005 | C15: Mitanshu Sharma | D15: PhD | E15: Ph.D. in Medical Technology | F15: 2020 | G15: 2025 | H15: Alumni | I15: Assistive Critical Care & Pressure Ulcer Prevention | J15: Dr. Shobhana Singh (IIT Jodhpur) & Dr. Nikhil Kothari (AIIMS Jodhpur) | K15: p20id005@iitj.ac.in | L15: - | M15: 0 | N15: - | O15: 1 | P15: App #202211060577: Pressure Ulcers or Bed Sores Preventing Air Bubble Based Mattress (Published) | App 202211060577: Pressure Ulcers / Bed Sores Preventing Air Bubble Mattress | Q15: 0 | R15: - | S15: 0 | T15: - | U15: - | V15: - | W15: Centre for Medical Technologies (IDRP) | X15: IIT Jodhpur Permanent Campus, NH 62, Karwar | Y15: Jodhpur | Z15: Rajasthan | AA15: 342030 | AB15: Official Cohort Registry (IIT Jodhpur MedTech Portal)
A16: 11 | B16: P20ID006 | C16: Monika Sharma | D16: PhD | E16: Ph.D. in Medical Technology | F16: 2020 | G16: 2025 | H16: Alumni | I16: Neuromuscular Assessment & Force-Sensor Biomechanics | J16: Dr. Pankaj Yadav (IIT Jodhpur) | K16: p20id006@iitj.ac.in | L16: - | M16: 0 | N16: - | O16: 1 | P16: App 202511106532: Force-Sensor-Based Tapping Device for Neuromuscular Assessment | Q16: 0 | R16: - | S16: 1 | T16: IBRO Exchange Fellowship 2026 | U16: - | V16: - | W16: Centre for Medical Technologies (IDRP) | X16: IIT Jodhpur Permanent Campus, NH 62, Karwar | Y16: Jodhpur | Z16: Rajasthan | AA16: 342030 | AB16: Official Cohort Registry (IIT Jodhpur MedTech Portal)
A17: 12 | B17: P20ID007 | C17: Om Lata Bhagat | D17: PhD | E17: Ph.D. in Medical Technology | F17: 2020 | G17: 2025 | H17: Alumni | I17: Medical Technology | J17: Faculty Board (IDRP / AIIMS-IIT Joint) | K17: p20id007@iitj.ac.in | L17: - | M17: 0 | N17: - | O17: 0 | P17: - | Q17: 0 | R17: - | S17: 0 | T17: - | U17: - | V17: - | W17: Centre for Medical Technologies (IDRP) | X17: IIT Jodhpur Permanent Campus, NH 62, Karwar | Y17: Jodhpur | Z17: Rajasthan | AA17: 342030 | AB17: Official Cohort Registry (IIT Jodhpur MedTech Portal)
... A30: 25 | B30: D20ID009 | C30: Yashraj Singh | D30: Dual Degree | E30: M.Tech-Ph.D. Dual Degree in Medical Technology | F30: 2020 | G30: 2025 | H30: Alumni | I30: Medical Technology | J30: Faculty Board (IDRP / AIIMS-IIT Joint) | K30: d20id009@iitj.ac.in | L30: - | M30: 0 | N30: - | O30: 0 | P30: - | Q30: 0 | R30: - | S30: 0 | T30: - | U30: - | V30: - | W30: Centre for Medical Technologies (IDRP) | X30: IIT Jodhpur Permanent Campus, NH 62, Karwar | Y30: Jodhpur | Z30: Rajasthan | AA30: 342030 | AB30: Official Cohort Registry (IIT Jodhpur MedTech Portal)
A32: 🎓 ADMISSION COHORT 2021 — Total Scholars: 17 (Masters: 6 | Ph.D.: 7 | Dual Degree: 4)
A33: S.No. | B33: Roll Number | C33: Student Scholar Name | D33: Program Level | E33: Degree Program | F33: Cohort Year | G33: Graduation Year | H33: Academic Status | I33: Specialization & Research Focus | J33: Faculty Supervisor(s) (IIT & AIIMS) | K33: Institutional Email | L33: Contact Phone | M33: Publications (Count) | N33: Publication Venues & Papers | O33: Patents (Count) | P33: Patent Filings & Application Nos. | Q33: Startups (Count) | R33: Startup Ventures & Student Roles | S33: Awards (Count) | T33: Awards, Honors & Hackathon Wins | U33: Date of Birth | V33: Gender | W33: Department / Centre | X33: Campus / Residential Address | Y33: City | Z33: State | AA33: Pincode | AB33: Verification Source URL / Provenance
A34: 1 | B34: M21ID001 | C34: Ajisha Ck | D34: Masters | E34: M.Tech in Medical Technology | F34: 2021 | G34: 2023 | H34: Alumni | I34: Medical Technology | J34: Faculty Board (IDRP / AIIMS-IIT Joint) | K34: m21id001@iitj.ac.in | L34: - | M34: 0 | N34: - | O34: 0 | P34: - | Q34: 0 | R34: - | S34: 0 | T34: - | U34: - | V34: - | W34: Centre for Medical Technologies (IDRP) | X34: IIT Jodhpur Permanent Campus, NH 62, Karwar | Y34: Jodhpur | Z34: Rajasthan | AA34: 342030 | AB34: Official Cohort Registry (IIT Jodhpur MedTech Portal)
A35: 2 | B35: M21ID002 | C35: Ajmal Jaleel | D35: Masters | E35: M.Tech in Medical Technology | F35: 2021 | G35: 2023 | H35: Alumni | I35: Surgical Ergonomics & Mattress Hygiene Management Systems | J35: Dr. Jayant Kumar Mohanta (IIT Jodhpur) | K35: m21id002@iitj.ac.in | L35: - | M35: 0 | N35: - | O35: 0 | P35: - | Q35: 1 | R35: ShilpinMed Technologies Pvt. Ltd. (Founder) | S35: 0 | T35: - | U35: - | V35: - | W35: Centre for Medical Technologies (IDRP) | X35: IIT Jodhpur Permanent Campus, NH 62, Karwar | Y35: Jodhpur | Z35: Rajasthan | AA35: 342030 | AB35: Official Cohort Registry (IIT Jodhpur MedTech Portal)
A36: 3 | B36: M21ID003 | C36: Divesh Kumar Awasthi | D36: Masters | E36: M.Tech in Medical Technology | F36: 2021 | G36: 2023 | H36: Alumni | I36: Ultrasound-Guided Interventional Syringe Systems | J36: Dr. Hardik Kothadia (IIT Jodhpur) | K36: m21id003@iitj.ac.in | L36: - | M36: 0 | N36: - | O36: 0 | P36: - | Q36: 1 | R36: Healyantra Medical Technologies Pvt. Ltd. (Co-Founder) | S36: 2 | T36: First patent ; TechEx Technology Transfer Hub funding | U36: - | V36: - | W36: Centre for Medical Technologies (IDRP) | X36: IIT Jodhpur Permanent Campus, NH 62, Karwar | Y36: Jodhpur | Z36: Rajasthan | AA36: 342030 | AB36: Official Cohort Registry (IIT Jodhpur MedTech Portal)
A37: 4 | B37: M21ID004 | C37: Gaurav Sawriya | D37: Masters | E37: M.Tech in Medical Technology | F37: 2021 | G37: 2023 | H37: Alumni | I37: Medical Technology | J37: Faculty Board (IDRP / AIIMS-IIT Joint) | K37: m21id004@iitj.ac.in | L37: - | M37: 0 | N37: - | O37: 0 | P37: - | Q37: 0 | R37: - | S37: 0 | T37: - | U37: - | V37: - | W37: Centre for Medical Technologies (IDRP) | X37: IIT Jodhpur Permanent Campus, NH 62, Karwar | Y37: Jodhpur | Z37: Rajasthan | AA37: 342030 | AB37: Official Cohort Registry (IIT Jodhpur MedTech Portal)
A38: 5 | B38: M21ID005 | C38: Harisharan R | D38: Masters | E38: M.Tech in Medical Technology | F38: 2021 | G38: 2023 | H38: Alumni | I38: ENT Devices & Cartilage Reshaping Instrumentation | J38: Prof. Ajay Agarwal (IIT Jodhpur) & Dr. Amit Goyal (AIIMS Jodhpur) | K38: m21id005@iitj.ac.in | L38: - | M38: 0 | N38: - | O38: 1 | P38: App 202411033887: Device for Reshaping Cartilage | Q38: 1 | R38: Caldor Health Technologies Pvt. Ltd. (Co-Founder) | S38: 1 | T38: US$100,000 raised for SWASAM | U38: - | V38: - | W38: Centre for Medical Technologies (IDRP) | X38: IIT Jodhpur Permanent Campus, NH 62, Karwar | Y38: Jodhpur | Z38: Rajasthan | AA38: 342030 | AB38: Official Cohort Registry (IIT Jodhpur MedTech Portal)
A39: 6 | B39: M21ID007 | C39: Varun Raman Khandelwal | D39: Masters | E39: M.Tech in Medical Technology | F39: 2021 | G39: 2023 | H39: Alumni | I39: Ultrasound-Guided Surgical Procedures & Clinical Devices | J39: Dr. Hardik Kothadia (IIT Jodhpur) | K39: m21id007@iitj.ac.in | L39: - | M39: 0 | N39: - | O39: 0 | P39: - | Q39: 1 | R39: Healyantra Medical Technologies Pvt. Ltd. (Director & Co-Founder) | S39: 3 | T39: First patent ; TechEx Technology Transfer Hub funding ; Winner of MEDHA 2022 | U39: - | V39: - | W39: Centre for Medical Technologies (IDRP) | X39: IIT Jodhpur Permanent Campus, NH 62, Karwar | Y39: Jodhpur | Z39: Rajasthan | AA39: 342030 | AB39: Official Cohort Registry (IIT Jodhpur MedTech Portal)
